{"trial_id": "0000", "hyperparameters": {"space": [{"class_name": "Int", "config": {"name": "units1", "default": null, "conditions": [], "min_value": 32, "max_value": 128, "step": 32, "sampling": "linear"}}, {"class_name": "Int", "config": {"name": "input_shape", "default": null, "conditions": [], "min_value": 10, "max_value": 100, "step": 10, "sampling": "linear"}}, {"class_name": "Int", "config": {"name": "units2", "default": null, "conditions": [], "min_value": 16, "max_value": 64, "step": 16, "sampling": "linear"}}, {"class_name": "Float", "config": {"name": "learning_rate", "default": 0.0001, "conditions": [], "min_value": 0.0001, "max_value": 0.01, "step": null, "sampling": "log"}}], "values": {"units1": 32, "input_shape": 40, "units2": 16, "learning_rate": 0.0021321979115285347, "tuner/epochs": 3, "tuner/initial_epoch": 0, "tuner/bracket": 2, "tuner/round": 0}}, "metrics": {"metrics": {}}, "score": null, "best_step": 0, "status": "FAILED", "message": "Traceback (most recent call last):\n  File \"/Users/govindkumargupta/Documents/No_Show_MLProject/venv/lib/python3.9/site-packages/keras_tuner/src/engine/base_tuner.py\", line 274, in _try_run_and_update_trial\n    self._run_and_update_trial(trial, *fit_args, **fit_kwargs)\n  File \"/Users/govindkumargupta/Documents/No_Show_MLProject/venv/lib/python3.9/site-packages/keras_tuner/src/engine/base_tuner.py\", line 239, in _run_and_update_trial\n    results = self.run_trial(trial, *fit_args, **fit_kwargs)\n  File \"/Users/govindkumargupta/Documents/No_Show_MLProject/venv/lib/python3.9/site-packages/keras_tuner/src/tuners/hyperband.py\", line 427, in run_trial\n    return super().run_trial(trial, *fit_args, **fit_kwargs)\n  File \"/Users/govindkumargupta/Documents/No_Show_MLProject/venv/lib/python3.9/site-packages/keras_tuner/src/engine/tuner.py\", line 314, in run_trial\n    obj_value = self._build_and_fit_model(trial, *args, **copied_kwargs)\n  File \"/Users/govindkumargupta/Documents/No_Show_MLProject/venv/lib/python3.9/site-packages/keras_tuner/src/engine/tuner.py\", line 233, in _build_and_fit_model\n    results = self.hypermodel.fit(hp, model, *args, **kwargs)\n  File \"/Users/govindkumargupta/Documents/No_Show_MLProject/venv/lib/python3.9/site-packages/keras_tuner/src/engine/hypermodel.py\", line 149, in fit\n    return model.fit(*args, **kwargs)\n  File \"/Users/govindkumargupta/Documents/No_Show_MLProject/venv/lib/python3.9/site-packages/keras/src/utils/traceback_utils.py\", line 122, in error_handler\n    raise e.with_traceback(filtered_tb) from None\n  File \"/Users/govindkumargupta/Documents/No_Show_MLProject/venv/lib/python3.9/site-packages/keras/src/layers/input_spec.py\", line 227, in assert_input_compatibility\n    raise ValueError(\nValueError: Exception encountered when calling Sequential.call().\n\n\u001b[1mInput 0 of layer \"dense\" is incompatible with the layer: expected axis -1 of input shape to have value 40, but received input with shape (None, 338)\u001b[0m\n\nArguments received by Sequential.call():\n  \u2022 inputs=tf.Tensor(shape=(None, 338), dtype=float32)\n  \u2022 training=True\n  \u2022 mask=None\n"}